<?xml version="1.0"?>
<robot name="simple_arm">
  <!-- Link 1 -->
  <link name="base_link">
    <visual>
      <geometry>
        <cylinder length="1.0" radius="0.1"/>
      </geometry>
      <material name="blue"/>
    </visual>
    <collision>
      <geometry>
        <cylinder length="1.0" radius="0.1"/>
      </geometry>
    </collision>
  </link>

  <!-- Link 2 -->
  <link name="end_effector">
    <visual>
      <geometry>
        <sphere radius="0.1"/>
      </geometry>
      <material name="green"/>
    </visual>
    <collision>
      <geometry>
        <sphere radius="0.1"/>
      </geometry>
    </collision>
  </link>

  <!-- Joint connecting the links -->
  <joint name="joint1" type="revolute">
    <parent link="base_link"/>
    <child link="end_effector"/>
    <origin xyz="0 0 0.5" rpy="0 0 0"/>
    <axis xyz="0 0 1"/>
    <limit lower="-1.57" upper="1.57" effort="10" velocity="1.0"/>
  </joint>
</robot>
